~/venture-associate$ npm test

> venture-associate@0.1.0 test
> jest

 PASS  src/components/__tests__/AuthForm.test.js
 PASS  src/api/__tests__/auth.test.js
 FAIL  src/api/__tests__/ventures.test.js
  ● Console

    console.log
      Server running on port 3001

      at Server.log (server.js:35:11)

    console.log
      Database connected successfully

      at BoundPool.log (src/db/config.js:23:11)

  ● Venture API › should create a venture linked to the user

    TypeError: app.address is not a function

      10 |     // Create a user and get the token for authentication
      11 |     const response = await request(app)
    > 12 |       .post('/api/auth/signup')
         |        ^
      13 |       .send({ email: 'test@example.com', password: 'password123' });
      14 |
      15 |     userId = response.body.user.id;

      at Test.serverAddress (node_modules/supertest/lib/test.js:46:22)
      at new Test (node_modules/supertest/lib/test.js:34:14)
      at Object.obj.<computed> [as post] (node_modules/supertest/index.js:43:18)
      at post (src/api/__tests__/ventures.test.js:12:8)
      at call (src/api/__tests__/ventures.test.js:2:1)
      at Generator.tryCatch (src/api/__tests__/ventures.test.js:2:1)
      at Generator._invoke [as next] (src/api/__tests__/ventures.test.js:2:1)
      at asyncGeneratorStep (src/api/__tests__/ventures.test.js:2:1)
      at asyncGeneratorStep (src/api/__tests__/ventures.test.js:2:1)
      at _next (src/api/__tests__/ventures.test.js:2:1)
      at Object.<anonymous> (src/api/__tests__/ventures.test.js:2:1)

A worker process has failed to exit gracefully and has been force exited. This is likely caused by tests leaking due to improper teardown. Try running with --detectOpenHandles to find leaks. Active timers can also cause this, ensure that .unref() was called on them.
Test Suites: 1 failed, 2 passed, 3 total
Tests:       1 failed, 4 passed, 5 total
Snapshots:   0 total
Time:        4.262 s
Ran all test suites.
 Environment updated. Reloading shell...
~/venture-associate$ 